[2022-08-20 14:31:54,124] {taskinstance.py:1179} INFO - Dependencies all met for <TaskInstance: ETL_toll_data.unzip_data scheduled__2022-08-15T00:00:00+00:00 [queued]>
[2022-08-20 14:31:54,135] {taskinstance.py:1179} INFO - Dependencies all met for <TaskInstance: ETL_toll_data.unzip_data scheduled__2022-08-15T00:00:00+00:00 [queued]>
[2022-08-20 14:31:54,136] {taskinstance.py:1376} INFO - 
--------------------------------------------------------------------------------
[2022-08-20 14:31:54,136] {taskinstance.py:1377} INFO - Starting attempt 1 of 2
[2022-08-20 14:31:54,136] {taskinstance.py:1378} INFO - 
--------------------------------------------------------------------------------
[2022-08-20 14:31:54,152] {taskinstance.py:1397} INFO - Executing <Task(BashOperator): unzip_data> on 2022-08-15 00:00:00+00:00
[2022-08-20 14:31:54,157] {standard_task_runner.py:52} INFO - Started process 793 to run task
[2022-08-20 14:31:54,160] {standard_task_runner.py:79} INFO - Running: ['***', 'tasks', 'run', 'ETL_toll_data', 'unzip_data', 'scheduled__2022-08-15T00:00:00+00:00', '--job-id', '83', '--raw', '--subdir', 'DAGS_FOLDER/final/final.py', '--cfg-path', '/tmp/tmpzdg2u_32', '--error-file', '/tmp/tmp07fgx9mu']
[2022-08-20 14:31:54,160] {standard_task_runner.py:80} INFO - Job 83: Subtask unzip_data
[2022-08-20 14:31:54,229] {task_command.py:371} INFO - Running <TaskInstance: ETL_toll_data.unzip_data scheduled__2022-08-15T00:00:00+00:00 [running]> on host d96844587567
[2022-08-20 14:31:54,305] {taskinstance.py:1591} INFO - Exporting the following env vars:
AIRFLOW_CTX_DAG_EMAIL=19447.iuh@gmail.com
AIRFLOW_CTX_DAG_OWNER=Ton
AIRFLOW_CTX_DAG_ID=ETL_toll_data
AIRFLOW_CTX_TASK_ID=unzip_data
AIRFLOW_CTX_EXECUTION_DATE=2022-08-15T00:00:00+00:00
AIRFLOW_CTX_TRY_NUMBER=1
AIRFLOW_CTX_DAG_RUN_ID=scheduled__2022-08-15T00:00:00+00:00
[2022-08-20 14:31:54,306] {subprocess.py:62} INFO - Tmp dir root location: 
 /tmp
[2022-08-20 14:31:54,307] {subprocess.py:74} INFO - Running command: ['bash', '-c', 'tar -xzvf /home/ton/***_docker/dags/final/tolldata.tgz -C /opt/***/dags/final/staging']
[2022-08-20 14:31:54,316] {subprocess.py:85} INFO - Output:
[2022-08-20 14:31:54,318] {subprocess.py:92} INFO - tar (child): /home/ton/***_docker/dags/final/tolldata.tgz: Cannot open: No such file or directory
[2022-08-20 14:31:54,319] {subprocess.py:92} INFO - tar (child): Error is not recoverable: exiting now
[2022-08-20 14:31:54,319] {subprocess.py:92} INFO - tar: Child returned status 2
[2022-08-20 14:31:54,319] {subprocess.py:92} INFO - tar: Error is not recoverable: exiting now
[2022-08-20 14:31:54,319] {subprocess.py:96} INFO - Command exited with return code 2
[2022-08-20 14:31:54,332] {taskinstance.py:1909} ERROR - Task failed with exception
Traceback (most recent call last):
  File "/home/airflow/.local/lib/python3.7/site-packages/airflow/operators/bash.py", line 195, in execute
    f'Bash command failed. The command returned a non-zero exit code {result.exit_code}.'
airflow.exceptions.AirflowException: Bash command failed. The command returned a non-zero exit code 2.
[2022-08-20 14:31:54,336] {taskinstance.py:1420} INFO - Marking task as UP_FOR_RETRY. dag_id=ETL_toll_data, task_id=unzip_data, execution_date=20220815T000000, start_date=20220820T143154, end_date=20220820T143154
[2022-08-20 14:31:54,352] {warnings.py:110} WARNING - /home/***/.local/lib/python3.7/site-packages/***/utils/email.py:119: PendingDeprecationWarning: Fetching SMTP credentials from configuration variables will be deprecated in a future release. Please set credentials using a connection instead.
  send_mime_email(e_from=mail_from, e_to=recipients, mime_msg=msg, conn_id=conn_id, dryrun=dryrun)

[2022-08-20 14:31:54,352] {configuration.py:552} WARNING - section/key [smtp/smtp_user] not found in config
[2022-08-20 14:31:54,353] {email.py:228} INFO - Email alerting: attempt 1
[2022-08-20 14:31:54,359] {configuration.py:552} WARNING - section/key [smtp/smtp_user] not found in config
[2022-08-20 14:31:54,359] {email.py:228} INFO - Email alerting: attempt 1
[2022-08-20 14:31:54,359] {taskinstance.py:1964} ERROR - Failed to send email to: ['19447.iuh@gmail.com']
Traceback (most recent call last):
  File "/home/airflow/.local/lib/python3.7/site-packages/airflow/models/taskinstance.py", line 1471, in _run_raw_task
    self._execute_task_with_callbacks(context, test_mode)
  File "/home/airflow/.local/lib/python3.7/site-packages/airflow/models/taskinstance.py", line 1618, in _execute_task_with_callbacks
    result = self._execute_task(context, task_orig)
  File "/home/airflow/.local/lib/python3.7/site-packages/airflow/models/taskinstance.py", line 1679, in _execute_task
    result = execute_callable(context=context)
  File "/home/airflow/.local/lib/python3.7/site-packages/airflow/operators/bash.py", line 195, in execute
    f'Bash command failed. The command returned a non-zero exit code {result.exit_code}.'
airflow.exceptions.AirflowException: Bash command failed. The command returned a non-zero exit code 2.

During handling of the above exception, another exception occurred:

Traceback (most recent call last):
  File "/home/airflow/.local/lib/python3.7/site-packages/airflow/models/taskinstance.py", line 2346, in email_alert
    send_email(task.email, subject, html_content)
  File "/home/airflow/.local/lib/python3.7/site-packages/airflow/utils/email.py", line 71, in send_email
    **kwargs,
  File "/home/airflow/.local/lib/python3.7/site-packages/airflow/utils/email.py", line 119, in send_email_smtp
    send_mime_email(e_from=mail_from, e_to=recipients, mime_msg=msg, conn_id=conn_id, dryrun=dryrun)
  File "/home/airflow/.local/lib/python3.7/site-packages/airflow/utils/email.py", line 230, in send_mime_email
    smtp_conn = _get_smtp_connection(smtp_host, smtp_port, smtp_timeout, smtp_ssl)
  File "/home/airflow/.local/lib/python3.7/site-packages/airflow/utils/email.py", line 264, in _get_smtp_connection
    else smtplib.SMTP(host=host, port=port, timeout=timeout)
  File "/usr/local/lib/python3.7/smtplib.py", line 251, in __init__
    (code, msg) = self.connect(host, port)
  File "/usr/local/lib/python3.7/smtplib.py", line 336, in connect
    self.sock = self._get_socket(host, port, self.timeout)
  File "/usr/local/lib/python3.7/smtplib.py", line 307, in _get_socket
    self.source_address)
  File "/usr/local/lib/python3.7/socket.py", line 728, in create_connection
    raise err
  File "/usr/local/lib/python3.7/socket.py", line 716, in create_connection
    sock.connect(sa)
OSError: [Errno 99] Cannot assign requested address

During handling of the above exception, another exception occurred:

Traceback (most recent call last):
  File "/home/airflow/.local/lib/python3.7/site-packages/airflow/models/taskinstance.py", line 1962, in handle_failure
    self.email_alert(error, task)
  File "/home/airflow/.local/lib/python3.7/site-packages/airflow/models/taskinstance.py", line 2348, in email_alert
    send_email(task.email, subject, html_content_err)
  File "/home/airflow/.local/lib/python3.7/site-packages/airflow/utils/email.py", line 71, in send_email
    **kwargs,
  File "/home/airflow/.local/lib/python3.7/site-packages/airflow/utils/email.py", line 119, in send_email_smtp
    send_mime_email(e_from=mail_from, e_to=recipients, mime_msg=msg, conn_id=conn_id, dryrun=dryrun)
  File "/home/airflow/.local/lib/python3.7/site-packages/airflow/utils/email.py", line 230, in send_mime_email
    smtp_conn = _get_smtp_connection(smtp_host, smtp_port, smtp_timeout, smtp_ssl)
  File "/home/airflow/.local/lib/python3.7/site-packages/airflow/utils/email.py", line 264, in _get_smtp_connection
    else smtplib.SMTP(host=host, port=port, timeout=timeout)
  File "/usr/local/lib/python3.7/smtplib.py", line 251, in __init__
    (code, msg) = self.connect(host, port)
  File "/usr/local/lib/python3.7/smtplib.py", line 336, in connect
    self.sock = self._get_socket(host, port, self.timeout)
  File "/usr/local/lib/python3.7/smtplib.py", line 307, in _get_socket
    self.source_address)
  File "/usr/local/lib/python3.7/socket.py", line 728, in create_connection
    raise err
  File "/usr/local/lib/python3.7/socket.py", line 716, in create_connection
    sock.connect(sa)
OSError: [Errno 99] Cannot assign requested address
[2022-08-20 14:31:54,373] {standard_task_runner.py:97} ERROR - Failed to execute job 83 for task unzip_data (Bash command failed. The command returned a non-zero exit code 2.; 793)
[2022-08-20 14:31:54,412] {local_task_job.py:156} INFO - Task exited with return code 1
[2022-08-20 14:31:54,456] {local_task_job.py:273} INFO - 0 downstream tasks scheduled from follow-on schedule check
